ERROR 2019-05-29 19:08:24,609 F:\git\blog\django_food\venv\lib\site-packages\django\utils\log.py log Internal Server Error: /xadmin/food/tags/add/
Traceback (most recent call last):
  File "F:\git\blog\django_food\venv\lib\site-packages\django\core\handlers\exception.py", line 34, in inner
    response = get_response(request)
  File "F:\git\blog\django_food\venv\lib\site-packages\django\core\handlers\base.py", line 115, in _get_response
    response = self.process_exception_by_middleware(e, request)
  File "F:\git\blog\django_food\venv\lib\site-packages\django\core\handlers\base.py", line 113, in _get_response
    response = wrapped_callback(request, *callback_args, **callback_kwargs)
  File "F:\git\blog\django_food\venv\lib\site-packages\xadmin\sites.py", line 300, in wrapper
    return self.admin_view(view, cacheable)(*args, **kwargs)
  File "F:\git\blog\django_food\venv\lib\site-packages\django\views\decorators\cache.py", line 44, in _wrapped_view_func
    response = view_func(request, *args, **kwargs)
  File "F:\git\blog\django_food\venv\lib\site-packages\xadmin\sites.py", line 208, in inner
    return view(request, *args, **kwargs)
  File "F:\git\blog\django_food\venv\lib\site-packages\xadmin\views\base.py", line 271, in view
    self = cls(request, *args, **kwargs)
  File "F:\git\blog\django_food\venv\lib\site-packages\xadmin\views\edit.py", line 85, in __init__
    super(ModelFormAdminView, self).__init__(request, *args, **kwargs)
  File "F:\git\blog\django_food\venv\lib\site-packages\xadmin\views\base.py", line 499, in __init__
    super(ModelAdminView, self).__init__(request, *args, **kwargs)
  File "F:\git\blog\django_food\venv\lib\site-packages\xadmin\views\base.py", line 266, in __init__
    self.init_request(*args, **kwargs)
  File "F:\git\blog\django_food\venv\lib\site-packages\xadmin\views\edit.py", line 375, in init_request
    self.prepare_form()
  File "F:\git\blog\django_food\venv\lib\site-packages\xadmin\views\base.py", line 80, in method
    return filter_chain(filters, len(filters) - 1, _inner_method, *args, **kwargs)
  File "F:\git\blog\django_food\venv\lib\site-packages\xadmin\views\base.py", line 49, in filter_chain
    return func()
  File "F:\git\blog\django_food\venv\lib\site-packages\xadmin\views\base.py", line 74, in _inner_method
    return func(self, *args, **kwargs)
  File "F:\git\blog\django_food\venv\lib\site-packages\xadmin\views\edit.py", line 141, in prepare_form
    self.model_form = self.get_model_form()
  File "F:\git\blog\django_food\venv\lib\site-packages\xadmin\views\base.py", line 80, in method
    return filter_chain(filters, len(filters) - 1, _inner_method, *args, **kwargs)
  File "F:\git\blog\django_food\venv\lib\site-packages\xadmin\views\base.py", line 63, in filter_chain
    return filter_chain(filters, token - 1, _inner_method, *args, **kwargs)
  File "F:\git\blog\django_food\venv\lib\site-packages\xadmin\views\base.py", line 49, in filter_chain
    return func()
  File "F:\git\blog\django_food\venv\lib\site-packages\xadmin\views\base.py", line 62, in _inner_method
    return fm(func if fargs[1] == '__' else func(), *args, **kwargs)
  File "F:\git\blog\django_food\venv\lib\site-packages\xadmin\plugins\quickform.py", line 30, in get_model_form
    return __()
  File "F:\git\blog\django_food\venv\lib\site-packages\xadmin\views\base.py", line 74, in _inner_method
    return func(self, *args, **kwargs)
  File "F:\git\blog\django_food\venv\lib\site-packages\xadmin\views\edit.py", line 185, in get_model_form
    return modelform_factory(self.model, **defaults)
  File "F:\git\blog\django_food\venv\lib\site-packages\django\forms\models.py", line 551, in modelform_factory
    return type(form)(class_name, (form,), form_class_attrs)
  File "F:\git\blog\django_food\venv\lib\site-packages\django\forms\models.py", line 264, in __new__
    message = message % (', '.join(missing_fields),
TypeError: sequence item 0: expected str instance, tuple found
ERROR 2019-05-31 11:15:13,671 F:\git\blog\django_food\venv\lib\site-packages\django\utils\log.py log Internal Server Error: /user_center/upload_food_article/
Traceback (most recent call last):
  File "F:\git\blog\django_food\venv\lib\site-packages\django\core\handlers\exception.py", line 34, in inner
    response = get_response(request)
  File "F:\git\blog\django_food\venv\lib\site-packages\django\core\handlers\base.py", line 115, in _get_response
    response = self.process_exception_by_middleware(e, request)
  File "F:\git\blog\django_food\venv\lib\site-packages\django\core\handlers\base.py", line 113, in _get_response
    response = wrapped_callback(request, *callback_args, **callback_kwargs)
  File "F:\git\blog\django_food\venv\lib\site-packages\django\views\generic\base.py", line 71, in view
    return self.dispatch(request, *args, **kwargs)
  File "F:\git\blog\django_food\venv\lib\site-packages\django\views\generic\base.py", line 97, in dispatch
    return handler(request, *args, **kwargs)
  File "F:\git\blog\django_food\apps\operation\views.py", line 658, in post
    url = reverse("xadmin:foodfoodarticle")
  File "F:\git\blog\django_food\venv\lib\site-packages\django\urls\base.py", line 90, in reverse
    return iri_to_uri(resolver._reverse_with_prefix(view, prefix, *args, **kwargs))
  File "F:\git\blog\django_food\venv\lib\site-packages\django\urls\resolvers.py", line 660, in _reverse_with_prefix
    raise NoReverseMatch(msg)
django.urls.exceptions.NoReverseMatch: Reverse for 'foodfoodarticle' not found. 'foodfoodarticle' is not a valid view function or pattern name.
ERROR 2019-05-31 11:16:16,319 F:\git\blog\django_food\venv\lib\site-packages\django\utils\log.py log Internal Server Error: /user_center/upload_food_article/
Traceback (most recent call last):
  File "F:\git\blog\django_food\venv\lib\site-packages\django\core\handlers\exception.py", line 34, in inner
    response = get_response(request)
  File "F:\git\blog\django_food\venv\lib\site-packages\django\core\handlers\base.py", line 115, in _get_response
    response = self.process_exception_by_middleware(e, request)
  File "F:\git\blog\django_food\venv\lib\site-packages\django\core\handlers\base.py", line 113, in _get_response
    response = wrapped_callback(request, *callback_args, **callback_kwargs)
  File "F:\git\blog\django_food\venv\lib\site-packages\django\views\generic\base.py", line 71, in view
    return self.dispatch(request, *args, **kwargs)
  File "F:\git\blog\django_food\venv\lib\site-packages\django\views\generic\base.py", line 97, in dispatch
    return handler(request, *args, **kwargs)
  File "F:\git\blog\django_food\apps\operation\views.py", line 658, in post
    url = reverse("food:foodarticle")
  File "F:\git\blog\django_food\venv\lib\site-packages\django\urls\base.py", line 90, in reverse
    return iri_to_uri(resolver._reverse_with_prefix(view, prefix, *args, **kwargs))
  File "F:\git\blog\django_food\venv\lib\site-packages\django\urls\resolvers.py", line 660, in _reverse_with_prefix
    raise NoReverseMatch(msg)
django.urls.exceptions.NoReverseMatch: Reverse for 'foodarticle' not found. 'foodarticle' is not a valid view function or pattern name.
